<mujoco model="stretch_description">
    <compiler convexhull="false" angle="radian" meshdir="./meshes/" />
    <size njmax="500" nconmax="100" />
    <asset>
        <mesh name="link_gripper" file="link_gripper.STL" />
        <mesh name="link_gripper_finger_left" file="link_gripper_finger_left.STL" scale="0.9 1 1" />
        <mesh name="link_gripper_fingertip_left" file="link_gripper_fingertip_left.STL" />
        <mesh name="link_gripper_finger_right" file="link_gripper_finger_right.STL" scale="0.9 1 1" />
        <mesh name="link_gripper_fingertip_right" file="link_gripper_fingertip_right.STL" />
        <mesh name="base_link" file="base_link.STL" />
        <mesh name="link_right_wheel" file="link_right_wheel.STL" />
        <mesh name="link_left_wheel" file="link_left_wheel.STL" />
        <mesh name="link_mast" file="link_mast.STL" />
        <mesh name="link_lift" file="link_lift.STL" />
        <mesh name="link_arm_l4" file="link_arm_l4.STL" />
        <mesh name="link_arm_l3" file="link_arm_l3.STL" />
        <mesh name="link_arm_l2" file="link_arm_l2.STL" />
        <mesh name="link_arm_l1" file="link_arm_l1.STL" />
        <mesh name="link_arm_l0" file="link_arm_l0.STL" />
        <mesh name="link_wrist_yaw" file="link_wrist_yaw.STL" />
        <mesh name="link_head" file="link_head.STL" />
        <mesh name="link_head_pan" file="link_head_pan.STL" />
        <mesh name="link_head_tilt" file="link_head_tilt.STL" />
        <mesh name="link_aruco_shoulder" file="link_aruco_shoulder.STL" />
        <mesh name="link_aruco_top_wrist" file="link_aruco_top_wrist.STL" />
        <mesh name="link_aruco_inner_wrist" file="link_aruco_inner_wrist.STL" />
        <mesh name="laser" file="laser.STL" />
        <mesh name="link_respeaker" file="link_respeaker.STL" />
    </asset>
    <worldbody>
        <body name="base_link" pos="0 0 0">
            <inertial pos="-0.109461 -0.000741019 0.0914915" quat="0.363732 0.610924 0.593498 0.377135" mass="1.07238" diaginertia="0.00433839 0.00393069 0.00289519" />
            <geom type="mesh" contype="0" conaffinity="0" group="1" rgba="0.792157 0.819608 0.933333 1" mesh="base_link" />
            <geom type="mesh" rgba="0.792157 0.819608 0.933333 1" mesh="base_link" />
            <body name="link_right_wheel" pos="-0.003 -0.15765 0.0508" quat="0.707107 -0.707107 0 0">
                <inertial pos="1.25555e-07 3.54749e-07 0.0239581" mass="0.00356715" diaginertia="3.33333e-06 3.33333e-06 3.33333e-06" />
                <joint name="joint_right_wheel" pos="0 0 0" axis="0 0 1" />
                <geom type="mesh" contype="0" conaffinity="0" group="1" rgba="0.792157 0.819608 0.933333 1" mesh="link_right_wheel" />
                <geom type="mesh" rgba="0.792157 0.819608 0.933333 1" mesh="link_right_wheel" />
            </body>
            <body name="link_left_wheel" pos="-0.003 0.15765 0.0508" quat="0.707107 -0.707107 0 0">
                <inertial pos="1.25555e-07 -3.54749e-07 -0.0239581" mass="0.00356715" diaginertia="3.33333e-06 3.33333e-06 3.33333e-06" />
                <joint name="joint_left_wheel" pos="0 0 0" axis="0 0 1" />
                <geom type="mesh" contype="0" conaffinity="0" group="1" rgba="0.792157 0.819608 0.933333 1" mesh="link_left_wheel" />
                <geom type="mesh" rgba="0.792157 0.819608 0.933333 1" mesh="link_left_wheel" />
            </body>
            <body name="link_mast" pos="-0.07 0.135 0.0284" quat="0.707099 0.707099 0.00327148 0.00327148">
                <inertial pos="0.00755819 0.773971 0.00647313" quat="0.681726 0.716499 0.0835256 -0.122073" mass="0.749143" diaginertia="0.0712536 0.0712199 5.4764e-05" />
                <geom type="mesh" contype="0" conaffinity="0" group="1" rgba="0.792157 0.819608 0.933333 1" mesh="link_mast" />
                <geom type="mesh" rgba="0.792157 0.819608 0.933333 1" mesh="link_mast" />
                <body name="link_lift" pos="-0.0369217 0.165471 -0.000341653" quat="0.502308 -0.502308 0.497681 0.497681">
                    <inertial pos="-0.0547636 0.038094 0.00933159" quat="0.10394 0.596796 0.278536 0.745284" mass="0.444821" diaginertia="0.00141842 0.00131916 0.000473669" />
                    <joint name="joint_lift" pos="0 0 0" axis="0 0 1" type="slide" limited="true" range="0 1.1" />
                    <geom type="mesh" contype="0" conaffinity="0" group="1" rgba="0.792157 0.819608 0.933333 1" mesh="link_lift" />
                    <geom type="mesh" rgba="0.792157 0.819608 0.933333 1" mesh="link_lift" />
                    <body name="link_arm_l4" pos="-0.25471 0 0" quat="0.499998 0.5 -0.500002 -0.5">
                        <inertial pos="-1.61247e-06 1.54716e-06 -0.0953253" quat="0.707107 -5.46934e-05 -1.13064e-06 0.707107" mass="0.0676525" diaginertia="8.13347e-05 8.13347e-05 8.13347e-05" />
                        <geom type="mesh" contype="0" conaffinity="0" group="1" rgba="0.792157 0.819608 0.933333 1" mesh="link_arm_l4" />
                        <geom type="mesh" rgba="0.792157 0.819608 0.933333 1" mesh="link_arm_l4" />
                        <body name="link_arm_l3" pos="0 0 0.013">
                            <inertial pos="-3.34873e-07 4.74113e-07 -0.097407" quat="0.707107 -1.40598e-05 2.41993e-06 0.707107" mass="0.0626921" diaginertia="7.68311e-05 7.68311e-05 7.68311e-05" />
                            <joint name="joint_arm_l3" pos="0 0 0" axis="0 0 1" type="slide" limited="true" range="0 0.13" />
                            <geom type="mesh" contype="0" conaffinity="0" group="1" rgba="0.792157 0.819608 0.933333 1" mesh="link_arm_l3" />
                            <geom type="mesh" rgba="0.792157 0.819608 0.933333 1" mesh="link_arm_l3" />
                            <body name="link_arm_l2" pos="0 0 0.013">
                                <inertial pos="-3.31044e-07 3.13422e-07 -0.0972559" quat="0.707107 -1.1118e-05 -3.03989e-07 0.707107" mass="0.0569074" diaginertia="7.01378e-05 7.01378e-05 7.01378e-05" />
                                <joint name="joint_arm_l2" pos="0 0 0" axis="0 0 1" type="slide" limited="true" range="0 0.13" />
                                <geom type="mesh" contype="0" conaffinity="0" group="1" rgba="0.792157 0.819608 0.933333 1" mesh="link_arm_l2" />
                                <geom type="mesh" rgba="0.792157 0.819608 0.933333 1" mesh="link_arm_l2" />
                                <body name="link_arm_l1" pos="0 0 0.013">
                                    <inertial pos="-3.36877e-07 3.05876e-07 -0.0969117" quat="0.991841 -0.127481 -8.0172e-06 -1.03045e-06" mass="0.0511764" diaginertia="3.19501e-05 3.19501e-05 3.19501e-05" />
                                    <joint name="joint_arm_l1" pos="0 0 0" axis="0 0 1" type="slide" limited="true" range="0 0.13" />
                                    <geom type="mesh" contype="0" conaffinity="0" group="1" rgba="0.792157 0.819608 0.933333 1" mesh="link_arm_l1" />
                                    <geom type="mesh" rgba="0.792157 0.819608 0.933333 1" mesh="link_arm_l1" />
                                    <body name="link_arm_l0" pos="0 0 -0.01375">
                                        <inertial pos="0.0230715 -0.00195116 -0.0360646" quat="0.737209 0.157918 0.14903 0.639824" mass="0.101241" diaginertia="0.000301835 0.000263236 5.63974e-05" />
                                        <joint name="joint_arm_l0" pos="0 0 0" axis="0 0 1" type="slide" limited="true" range="0 0.13" />
                                        <geom type="mesh" contype="0" conaffinity="0" group="1" rgba="0.792157 0.819608 0.933333 1" mesh="link_arm_l0" />
                                        <geom type="mesh" rgba="0.792157 0.819608 0.933333 1" mesh="link_arm_l0" />
                                        <body name="link_wrist_yaw" pos="0.083 -0.03075 0" quat="0.707105 0.707108 0 0">
                                            <inertial pos="-8.02796e-06 1.93811e-05 0.0189467" quat="0.999981 -0.00562821 -0.0023312 1.31207e-05" mass="0.0405399" diaginertia="1.46712e-09 1.46712e-09 1.46712e-09" />
                                            <joint name="joint_wrist_yaw" pos="0 0 0" axis="0 0 -1" limited="true" range="-1.75 4" />
                                            <geom type="mesh" contype="0" conaffinity="0" group="1" rgba="0.792157 0.819608 0.933333 1" mesh="link_wrist_yaw" />
                                            <geom type="mesh" rgba="0.792157 0.819608 0.933333 1" mesh="link_wrist_yaw" />
                                            <body name="link_gripper" pos="0 0 0" quat="9.38184e-07 0.707105 -0.707108 -9.38187e-07">
                                                <inertial pos="-0.0170229 0.013141 -0.0371615" quat="-0.0073901 0.451945 0.250435 0.856139" mass="0.101903" diaginertia="5.16962e-05 4.19152e-05 1.25597e-05" />
                                                <geom type="mesh" contype="0" conaffinity="0" group="1" rgba="0.792157 0.819608 0.933333 1" mesh="link_gripper" />
                                                <geom type="mesh" rgba="0.792157 0.819608 0.933333 1" mesh="link_gripper" />
                                                <body name="link_gripper_finger_left" pos="-0.047231 -0.010151 -0.04679" quat="-3.54804e-06 -0.25882 -9.50698e-07 0.965926">
                                                    <inertial pos="0.0945047 0.0124301 0" mass="0.0476208" diaginertia="3.33333e-09 3.33333e-09 3.33333e-09" />
                                                    <joint name="joint_gripper_finger_left" pos="0 0 0" axis="0 0 1" limited="true" range="-0.6 0.6" />
                                                    <geom type="mesh" contype="0" conaffinity="0" group="1" rgba="0.792157 0.819608 0.933333 1" mesh="link_gripper_finger_left" />
                                                    <geom type="mesh" rgba="0.792157 0.819608 0.933333 1" mesh="link_gripper_finger_left" />
                                                    <body name="link_gripper_fingertip_left" pos="0.171099 0.014912 0" quat="0.2046 -0.204601 0.676861 -0.676858">
                                                        <inertial pos="-3.16381e-08 -2.91409e-09 0.0081258" mass="0.0038216" diaginertia="0 0 0" />
                                                        <geom type="mesh" contype="0" conaffinity="0" group="1" rgba="0.25098 0.25098 0.25098 1" mesh="link_gripper_fingertip_left" />
                                                        <geom type="mesh" rgba="0.25098 0.25098 0.25098 1" mesh="link_gripper_fingertip_left" />
                                                    </body>
                                                </body>
                                                <body name="link_gripper_finger_right" pos="-0.047231 0.010049 -0.04679" quat="-3.54804e-06 0.965926 9.50698e-07 0.25882">
                                                    <inertial pos="-0.0945047 -0.0124301 0" mass="0.0476208" diaginertia="0 0 0" />
                                                    <joint name="joint_gripper_finger_right" pos="0 0 0" axis="0 0 1" limited="true" range="-0.6 0.6" />
                                                    <geom type="mesh" contype="0" conaffinity="0" group="1" rgba="0.792157 0.819608 0.933333 1" mesh="link_gripper_finger_right" />
                                                    <geom type="mesh" rgba="0.792157 0.819608 0.933333 1" mesh="link_gripper_finger_right" />
                                                    <body name="link_gripper_fingertip_right" pos="-0.171099 -0.014912 0" quat="0.676863 -0.676865 -0.204586 0.204586">
                                                        <inertial pos="2.59386e-08 6.70949e-09 0.0081258" mass="0.0038216" diaginertia="3.33333e-09 3.33333e-09 3.33333e-09" />
                                                        <geom type="mesh" contype="0" conaffinity="0" group="1" rgba="0.25098 0.25098 0.25098 1" mesh="link_gripper_fingertip_right" />
                                                        <geom type="mesh" rgba="0.25098 0.25098 0.25098 1" mesh="link_gripper_fingertip_right" />
                                                    </body>
                                                </body>
                                                <body name="link_grasp_center" pos="-0.205478 0 -0.138154" quat="6.82679e-06 0 0 1">
                                                    <inertial pos="0 0 0" mass="0.1" diaginertia="1 1 1" />
                                                </body>
                                            </body>
                                        </body>
                                        <body name="link_aruco_top_wrist" pos="0.04725 0.029285 0" quat="0 0 0.707107 0.707107">
                                            <inertial pos="0 0 -0.000125" mass="0.000225" diaginertia="0 0 0" />
                                            <geom type="mesh" contype="0" conaffinity="0" group="1" rgba="0.792157 0.819608 0.933333 1" mesh="link_aruco_top_wrist" />
                                            <geom type="mesh" rgba="0.792157 0.819608 0.933333 1" mesh="link_aruco_top_wrist" />
                                        </body>
                                        <body name="link_aruco_inner_wrist" pos="0.04725 -0.0119 -0.02725" quat="0 0 1 0">
                                            <inertial pos="0 0 -0.000125" mass="0.000225" diaginertia="0 0 0" />
                                            <geom type="mesh" contype="0" conaffinity="0" group="1" rgba="0.792157 0.819608 0.933333 1" mesh="link_aruco_inner_wrist" />
                                            <geom type="mesh" rgba="0.792157 0.819608 0.933333 1" mesh="link_aruco_inner_wrist" />
                                        </body>
                                    </body>
                                </body>
                            </body>
                        </body>
                    </body>
                    <body name="link_aruco_shoulder" pos="-0.0133769 0.0558541 0.0861368">
                        <inertial pos="0 0 -0.000125" mass="0.000399142" diaginertia="0 0 0" />
                        <geom type="mesh" contype="0" conaffinity="0" group="1" rgba="0.792157 0.819608 0.933333 1" mesh="link_aruco_shoulder" />
                        <geom type="mesh" rgba="0.792157 0.819608 0.933333 1" mesh="link_aruco_shoulder" />
                    </body>
                </body>
                <body name="link_head" pos="0 1.33 0" quat="-0.497673 0.497668 0.502321 0.502316">
                    <inertial pos="0.0372934 0.0455094 0.0281137" quat="0.976846 0.0331685 0.145076 -0.153705" mass="0.129455" diaginertia="3.11232e-05 2.66092e-05 1.30539e-05" />
                    <geom type="mesh" contype="0" conaffinity="0" group="1" rgba="0.792157 0.819608 0.933333 1" mesh="link_head" />
                    <geom type="mesh" rgba="0.792157 0.819608 0.933333 1" mesh="link_head" />
                    <body name="link_head_pan" pos="0.135 0.0731 -0.003" quat="0.707105 0 0 0.707108">
                        <inertial pos="-0.001162 0.0130366 0.0013763" quat="0.966863 0.254553 0.0184323 0.00623609" mass="0.0358583" diaginertia="2.76263e-05 2.75153e-05 1.10969e-07" />
                        <joint name="joint_head_pan" pos="0 0 0" axis="0 0 1" limited="true" range="-3.9 1.5" />
                        <geom type="mesh" contype="0" conaffinity="0" group="1" rgba="0.792157 0.819608 0.933333 1" mesh="link_head_pan" />
                        <geom type="mesh" rgba="0.792157 0.819608 0.933333 1" mesh="link_head_pan" />
                        <body name="link_head_tilt" pos="-0.0013 0.027507 -0.053311" quat="0.707105 0.707108 0 0">
                            <inertial pos="0.00920211 -0.0279725 0.030658" quat="0.512449 0.492238 0.514322 0.480177" mass="0.0701242" diaginertia="4.11581e-05 2.38351e-05 1.7323e-05" />
                            <joint name="joint_head_tilt" pos="0 0 0" axis="0 0 1" limited="true" range="-1.53 0.79" />
                            <geom type="mesh" contype="0" conaffinity="0" group="1" rgba="0.792157 0.819608 0.933333 1" mesh="link_head_tilt" />
                            <geom type="mesh" rgba="0.792157 0.819608 0.933333 1" mesh="link_head_tilt" />
                            <body name="camera_bottom_screw_frame" pos="0.03 -0.0122 0.0182">
                                <inertial pos="0 0 0" mass="0" diaginertia="1 1 1" />
                                <body name="camera_link" pos="0.0106 0.0175 0.0125">
                                    <inertial pos="0 0 0" quat="0.707107 0.707107 0 0" mass="0.564" diaginertia="0.00388124 0.00387926 0.00049894" />
                                    <geom size="0.012525 0.045 0.0125" pos="0 -0.0175 0" type="box" />
                                    <body name="camera_depth_frame" pos="0 0 0">
                                        <inertial pos="0 0 0" mass="0" diaginertia="1 1 1" />
                                        <body name="camera_depth_optical_frame" pos="0 0 0" quat="0.5 -0.5 0.5 -0.5">
                                            <inertial pos="0 0 0" mass="0" diaginertia="1 1 1" />
                                        </body>
                                    </body>
                                    <body name="camera_infra1_frame" pos="0 0 0">
                                        <inertial pos="0 0 0" mass="0" diaginertia="1 1 1" />
                                        <body name="camera_infra1_optical_frame" pos="0 0 0" quat="0.5 -0.5 0.5 -0.5">
                                            <inertial pos="0 0 0" mass="0" diaginertia="1 1 1" />
                                        </body>
                                    </body>
                                    <body name="camera_infra2_frame" pos="0 -0.05 0">
                                        <inertial pos="0 0 0" mass="0" diaginertia="1 1 1" />
                                        <body name="camera_infra2_optical_frame" pos="0 0 0" quat="0.5 -0.5 0.5 -0.5">
                                            <inertial pos="0 0 0" mass="0" diaginertia="1 1 1" />
                                        </body>
                                    </body>
                                    <body name="camera_color_frame" pos="0 0.015 0">
                                        <inertial pos="0 0 0" mass="0" diaginertia="1 1 1" />
                                        <body name="camera_color_optical_frame" pos="0 0 0" quat="0.5 -0.5 0.5 -0.5">
                                            <inertial pos="0 0 0" mass="0" diaginertia="1 1 1" />
                                        </body>
                                    </body>
                                </body>
                            </body>
                        </body>
                    </body>
                </body>
                <body name="respeaker_base" pos="1.09075e-05 1.36992 0.00303573" quat="0 0 0.707107 0.707107">
                    <inertial pos="-0.000780829 0.00765742 -0.00424883" quat="0.365137 0.23346 -0.423502 0.795498" mass="0.00969129" diaginertia="9.21173e-07 8.83665e-07 2.03311e-07" />
                    <geom type="mesh" contype="0" conaffinity="0" group="1" rgba="0.792157 0.819608 0.933333 1" mesh="link_respeaker" />
                    <geom type="mesh" rgba="0.792157 0.819608 0.933333 1" mesh="link_respeaker" />
                </body>
            </body>
            <body name="link_aruco_right_base" pos="-0.005 -0.130497 0.159748" quat="0.707107 0 0 -0.707107">
                <inertial pos="0 0 -5e-07" mass="3.6e-06" diaginertia="0 0 0" />
                <geom type="mesh" contype="0" conaffinity="0" group="1" rgba="0.792157 0.819608 0.933333 1" mesh="link_head_tilt" />
                <geom type="mesh" rgba="0.792157 0.819608 0.933333 1" mesh="link_head_tilt" />
            </body>
            <body name="link_aruco_left_base" pos="-0.005 0.130497 0.159748" quat="0.707107 0 0 -0.707107">
                <inertial pos="0 0 -5e-07" mass="3.6e-06" diaginertia="0 0 0" />
                <geom type="mesh" contype="0" conaffinity="0" group="1" rgba="0.792157 0.819608 0.933333 1" mesh="link_head_tilt" />
                <geom type="mesh" rgba="0.792157 0.819608 0.933333 1" mesh="link_head_tilt" />
            </body>
            <body name="laser" pos="0.0005028 0 0.1664" quat="0 0 0 -1">
                <inertial pos="0 0 -0.000755956" mass="0.0749979" diaginertia="0 0 0" />
                <geom type="mesh" contype="0" conaffinity="0" group="1" rgba="0.25098 0.25098 0.25098 1" mesh="laser" />
                <geom type="mesh" rgba="0.25098 0.25098 0.25098 1" mesh="laser" />
            </body>
        </body>
    </worldbody>
</mujoco>
