<robot name="human">
	<link name = "base">
		<inertial>
			<origin rpy = "0 0 0"  xyz = "0 0 0" />
			<mass value =  "0.0001" />
			<inertia ixx = "0.0001" ixy = "0" ixz = "0" iyy = "0.0001" iyz = "0" izz = "0.0001" />
		</inertial>
	</link>
	<link name = "root">
		<inertial>
			<origin rpy = "0 0 0"  xyz = "0 0 0" />
			<mass value =  "15" />
			<inertia ixx = "0.1" ixy = "0" ixz = "0" iyy = "0.1" iyz = "0" izz = "0.1" />
		</inertial>
		<collision>
			<origin rpy = "0 0 0"  xyz = "0 0 0" />
			<geometry>
				<sphere radius="0.07" />
			</geometry>
		</collision>
	</link>
	<joint name="root" type="floating">
		<parent link = "base" />
		<child link = "root" />
		<origin rpy = "0 0 0  " xyz ="0 0 0"  />
	</joint>
	<link name = "root_dammy_ori">
		<inertial>
			<origin rpy = "0 0 0"  xyz = "0 0 0" />
			<mass value =  "0.00001" />
			<inertia ixx = "0.1" ixy = "0" ixz = "0" iyy = "0.1" iyz = "0" izz = "0.1" />
		</inertial>
		<collision>
			<origin rpy = "0 0 0"  xyz = "0 0 0" />
			<geometry>
				<sphere radius="0.00000004" />
			</geometry>
		</collision>
	</link>
	<joint name="root_dammy_ori" type="fixed">
		<parent link = "root" />
		<child link = "root_dammy_ori" />
		<origin rpy = "-1.57 -1.57 0 " xyz ="0 0 0"  />
	</joint>
	<link name = "left_hip">
		<inertial>
			<origin rpy = "0 0 0"  xyz = "0 0 0" />
			<mass value =  "1e-05" />
			<inertia ixx = "0.1" ixy = "0" ixz = "0" iyy = "0.1" iyz = "0" izz = "0.1" />
		</inertial>
		<collision>
			<origin rpy = "0 0 0"  xyz = "0 0 0" />
			<geometry>
				<sphere radius="1e-06" />
			</geometry>
		</collision>
	</link>
	<link name = "left_hip_f1">
		<inertial>
			<origin rpy = "0 0 0"  xyz = "0 0 0" />
			<mass value =  "0" />
			<inertia ixx = "0.0" ixy = "0" ixz = "0" iyy = "0.0" iyz = "0" izz = "0.0" />
		</inertial>
		<collision>
			<origin rpy = "0 0 0"  xyz = "0 0 0" />
			<geometry>
				<sphere radius="0" />
			</geometry>
		</collision>
	</link>
	<link name = "left_hip_f2">
		<inertial>
			<origin rpy = "0 0 0"  xyz = "0 0 0" />
			<mass value =  "0" />
			<inertia ixx = "0.0" ixy = "0" ixz = "0" iyy = "0.0" iyz = "0" izz = "0.0" />
		</inertial>
		<collision>
			<origin rpy = "0 0 0"  xyz = "0 0 0" />
			<geometry>
				<sphere radius="0" />
			</geometry>
		</collision>
	</link>
	<joint name="left_hip_rx" type="revolute">
		<parent link = "root_dammy_ori" />
		<child link = "left_hip" />
		<limit effort="1000.0" lower= "-2.5" upper= "1.4" velocity="0.5" />
		<origin rpy = "0 0 0" xyz ="-0.0186897 0.0574607 -0.0816852"  />
		<axis xyz = "0.0 1.0 0.0" />
	</joint>
    <joint name="left_hip_ry" type="revolute">
		<parent link = "root_dammy_ori" />
		<child link = "left_hip_f1" />
		<limit effort="1000.0" lower= "-0.6" upper= "0.6" velocity="0.5" />
	<origin rpy = "0 0 0" xyz ="-0.0186897 0.0574607 -0.0816852"  />
		<axis xyz = "0.0 1.0 0.0" />
	</joint>
	<joint name="left_hip_rz" type="revolute">
		<parent link = "root_dammy_ori" />
		<child link = "left_hip_f2" />
		<limit effort="1000.0" lower= "-0.8" upper= "1.4" velocity="0.5" />
		<origin rpy = "0 0 0" xyz ="-0.0186897 0.0574607 -0.0816852"  />
		<axis xyz = "0.0 1.0 0.0" />
	</joint>

</robot>