<mujoco model="humanoid">
  <compiler angle="degree" inertiafromgeom="true" coordinate="global"/>
  <visual>
    <headlight ambient=".4 .4 .4" diffuse=".8 .8 .8" specular="0.1 0.1 0.1"/>
    <map znear=".01"/>
    <quality shadowsize="2048"/>
  </visual>
  <default>
    <joint damping="0.0" armature="0.01" stiffness="0.0" limited="true"/>
    <geom conaffinity="1" condim="1" contype="7" margin="0.001" rgba="0.8 0.6 .4 1"/>
  </default>
  <statistic extent="3" center="0 0 1"/>
  <option timestep="0.00222222222"/>
  <asset>
    <texture type="skybox" builtin="gradient" rgb1=".4 .5 .6" rgb2="0 0 0" width="100" height="100"/>
    <texture builtin="flat" height="1278" mark="cross" markrgb="1 1 1" name="texgeom" random="0.01" rgb1="0.8 0.6 0.4" rgb2="0.8 0.6 0.4" type="cube" width="127"/>
    <texture builtin="checker" height="100" name="texplane" rgb1="0 0 0" rgb2="0.8 0.8 0.8" type="2d" width="100"/>
    <material name="MatPlane" reflectance="0.5" shininess="1" specular="1" texrepeat="60 60" texture="texplane"/>
    <material name="geom" texture="texgeom" texuniform="true"/>
    <mesh file="/home/louis/Documents/Projects/uhc-tri/assets/mujoco_models/geom/Pelvis.stl"/>
    <mesh file="/home/louis/Documents/Projects/uhc-tri/assets/mujoco_models/geom/L_Hip.stl"/>
    <mesh file="/home/louis/Documents/Projects/uhc-tri/assets/mujoco_models/geom/R_Hip.stl"/>
    <mesh file="/home/louis/Documents/Projects/uhc-tri/assets/mujoco_models/geom/Torso.stl"/>
    <mesh file="/home/louis/Documents/Projects/uhc-tri/assets/mujoco_models/geom/L_Knee.stl"/>
    <mesh file="/home/louis/Documents/Projects/uhc-tri/assets/mujoco_models/geom/R_Knee.stl"/>
    <mesh file="/home/louis/Documents/Projects/uhc-tri/assets/mujoco_models/geom/Spine.stl"/>
    <mesh file="/home/louis/Documents/Projects/uhc-tri/assets/mujoco_models/geom/L_Ankle.stl"/>
    <mesh file="/home/louis/Documents/Projects/uhc-tri/assets/mujoco_models/geom/R_Ankle.stl"/>
    <mesh file="/home/louis/Documents/Projects/uhc-tri/assets/mujoco_models/geom/Chest.stl"/>
    <mesh file="/home/louis/Documents/Projects/uhc-tri/assets/mujoco_models/geom/L_Toe.stl"/>
    <mesh file="/home/louis/Documents/Projects/uhc-tri/assets/mujoco_models/geom/R_Toe.stl"/>
    <mesh file="/home/louis/Documents/Projects/uhc-tri/assets/mujoco_models/geom/Neck.stl"/>
    <mesh file="/home/louis/Documents/Projects/uhc-tri/assets/mujoco_models/geom/L_Thorax.stl"/>
    <mesh file="/home/louis/Documents/Projects/uhc-tri/assets/mujoco_models/geom/R_Thorax.stl"/>
    <mesh file="/home/louis/Documents/Projects/uhc-tri/assets/mujoco_models/geom/Head.stl"/>
    <mesh file="/home/louis/Documents/Projects/uhc-tri/assets/mujoco_models/geom/L_Shoulder.stl"/>
    <mesh file="/home/louis/Documents/Projects/uhc-tri/assets/mujoco_models/geom/R_Shoulder.stl"/>
    <mesh file="/home/louis/Documents/Projects/uhc-tri/assets/mujoco_models/geom/L_Elbow.stl"/>
    <mesh file="/home/louis/Documents/Projects/uhc-tri/assets/mujoco_models/geom/R_Elbow.stl"/>
    <mesh file="/home/louis/Documents/Projects/uhc-tri/assets/mujoco_models/geom/L_Wrist.stl"/>
    <mesh file="/home/louis/Documents/Projects/uhc-tri/assets/mujoco_models/geom/R_Wrist.stl"/>
    <mesh file="/home/louis/Documents/Projects/uhc-tri/assets/mujoco_models/geom/L_Hand.stl"/>
    <mesh file="/home/louis/Documents/Projects/uhc-tri/assets/mujoco_models/geom/R_Hand.stl"/>
  </asset>
  <worldbody>
    <geom conaffinity="1" condim="3" name="floor" pos="0 0 0" rgba="0.8 0.9 0.8 1" size="100 100 .2" type="plane" material="MatPlane"/>
    <body name="Pelvis" pos="-0.0022 -0.2408 0.0286" quat="1.0000 0.0000 0.0000 0.0000">
      <joint name="Pelvis" pos="-0.0022 -0.2408 0.0286" limited="false" type="free" armature="0.01" damping="0" stiffness="0" frictionloss="1000"/>
      <geom type="mesh" mesh="Pelvis" contype="1" conaffinity="1" size="1 1 1" density="1000"/>
      <body name="L_Hip" pos="0.0616 -0.3206 0.0371" quat="1.0000 0.0000 0.0000 0.0000">
        <joint name="L_Hip_z" type="hinge" pos="0.0616 -0.3206 0.0371" axis="0 0 1" range="-35.0000 35.0000" armature="0.01" damping="0" stiffness="0" frictionloss="1000"/>
        <joint name="L_Hip_y" type="hinge" pos="0.0616 -0.3206 0.0371" axis="0 1 0" range="-35.0000 35.0000" armature="0.01" damping="0" stiffness="0" frictionloss="1000"/>
        <joint name="L_Hip_x" type="hinge" pos="0.0616 -0.3206 0.0371" axis="1 0 0" range="-35.0000 35.0000" armature="0.01" damping="0" stiffness="0" frictionloss="1000"/>
        <body name="L_Knee" pos="-0.0164 -0.5831 0.3134" quat="1.0000 0.0000 0.0000 0.0000">
          <joint name="L_Knee_z" type="hinge" pos="-0.0164 -0.5831 0.3134" axis="0 0 1" range="-11.2500 11.2500" armature="0.01" damping="0" stiffness="0" frictionloss="1000"/>
          <joint name="L_Knee_y" type="hinge" pos="-0.0164 -0.5831 0.3134" axis="0 1 0" range="-11.2500 11.2500" armature="0.01" damping="0" stiffness="0" frictionloss="1000"/>
          <joint name="L_Knee_x" type="hinge" pos="-0.0164 -0.5831 0.3134" axis="1 0 0" range="-11.2500 180.0000" armature="0.01" damping="0" stiffness="0" frictionloss="1000"/>
          <geom type="mesh" mesh="L_Knee" contype="1" conaffinity="1" size="1 1 1" density="1000"/>
          <body name="L_Ankle" pos="0.0536 -0.9339 0.0771" quat="1.0000 0.0000 0.0000 0.0000">
            <joint name="L_Ankle_z" type="hinge" pos="0.0536 -0.9339 0.0771" axis="0 0 1" range="-90.0000 90.0000" armature="0.01" damping="0" stiffness="0" frictionloss="1000"/>
            <joint name="L_Ankle_y" type="hinge" pos="0.0536 -0.9339 0.0771" axis="0 1 0" range="-90.0000 90.0000" armature="0.01" damping="0" stiffness="0" frictionloss="1000"/>
            <joint name="L_Ankle_x" type="hinge" pos="0.0536 -0.9339 0.0771" axis="1 0 0" range="-90.0000 90.0000" armature="0.01" damping="0" stiffness="0" frictionloss="1000"/>
            <geom type="mesh" mesh="L_Ankle" contype="1" conaffinity="1" size="1 1 1" density="1000"/>
            <body name="L_Toe" pos="0.0839 -1.072 0.092" quat="1.0000 0.0000 0.0000 0.0000">
              <joint name="L_Toe_z" type="hinge" pos="0.0839 -1.072 0.092" axis="0 0 1" range="-45.0000 45.0000" armature="0.01" damping="0" stiffness="0" frictionloss="1000"/>
              <joint name="L_Toe_y" type="hinge" pos="0.0839 -1.072 0.092" axis="0 1 0" range="-45.0000 45.0000" armature="0.01" damping="0" stiffness="0" frictionloss="1000"/>
              <joint name="L_Toe_x" type="hinge" pos="0.0839 -1.072 0.092" axis="1 0 0" range="-90.0000 90.0000" armature="0.01" damping="0" stiffness="0" frictionloss="1000"/>
              <geom type="mesh" mesh="L_Toe" contype="1" conaffinity="1" size="1 1 1" density="1000"/>
            </body>
          </body>
        </body>
      </body>
      <body name="R_Hip" pos="-0.0566 -0.3346 0.0443" quat="1.0000 0.0000 0.0000 0.0000">
        <joint name="R_Hip_z" type="hinge" pos="-0.0566 -0.3346 0.0443" axis="0 0 1" range="-35.0000 35.0000" armature="0.01" damping="0" stiffness="0" frictionloss="1000"/>
        <joint name="R_Hip_y" type="hinge" pos="-0.0566 -0.3346 0.0443" axis="0 1 0" range="-35.0000 35.0000" armature="0.01" damping="0" stiffness="0" frictionloss="1000"/>
        <joint name="R_Hip_x" type="hinge" pos="-0.0566 -0.3346 0.0443" axis="1 0 0" range="-35.0000 35.0000" armature="0.01" damping="0" stiffness="0" frictionloss="1000"/>
        <geom type="mesh" mesh="R_Hip" contype="1" conaffinity="1" size="1 1 1" density="1000"/>
        <body name="R_Knee" pos="-0.1514 -0.6945 0.1473" quat="1.0000 0.0000 0.0000 0.0000">
          <joint name="R_Knee_z" type="hinge" pos="-0.1514 -0.6945 0.1473" axis="0 0 1" range="-11.2500 11.2500" armature="0.01" damping="0" stiffness="0" frictionloss="1000"/>
          <joint name="R_Knee_y" type="hinge" pos="-0.1514 -0.6945 0.1473" axis="0 1 0" range="-11.2500 11.2500" armature="0.01" damping="0" stiffness="0" frictionloss="1000"/>
          <joint name="R_Knee_x" type="hinge" pos="-0.1514 -0.6945 0.1473" axis="1 0 0" range="-11.2500 180.0000" armature="0.01" damping="0" stiffness="0" frictionloss="1000"/>
          <geom type="mesh" mesh="R_Knee" contype="1" conaffinity="1" size="1 1 1" density="1000"/>
          <body name="R_Ankle" pos="-0.0307 -1.0987 0.148" quat="1.0000 0.0000 0.0000 0.0000">
            <joint name="R_Ankle_z" type="hinge" pos="-0.0307 -1.0987 0.148" axis="0 0 1" range="-90.0000 90.0000" armature="0.01" damping="0" stiffness="0" frictionloss="1000"/>
            <joint name="R_Ankle_y" type="hinge" pos="-0.0307 -1.0987 0.148" axis="0 1 0" range="-90.0000 90.0000" armature="0.01" damping="0" stiffness="0" frictionloss="1000"/>
            <joint name="R_Ankle_x" type="hinge" pos="-0.0307 -1.0987 0.148" axis="1 0 0" range="-90.0000 90.0000" armature="0.01" damping="0" stiffness="0" frictionloss="1000"/>
            <geom type="mesh" mesh="R_Ankle" contype="1" conaffinity="1" size="1 1 1" density="1000"/>
            <body name="R_Toe" pos="-0.0767 -1.2392 0.1628" quat="1.0000 0.0000 0.0000 0.0000">
              <joint name="R_Toe_z" type="hinge" pos="-0.0767 -1.2392 0.1628" axis="0 0 1" range="-45.0000 45.0000" armature="0.01" damping="0" stiffness="0" frictionloss="1000"/>
              <joint name="R_Toe_y" type="hinge" pos="-0.0767 -1.2392 0.1628" axis="0 1 0" range="-45.0000 45.0000" armature="0.01" damping="0" stiffness="0" frictionloss="1000"/>
              <joint name="R_Toe_x" type="hinge" pos="-0.0767 -1.2392 0.1628" axis="1 0 0" range="-90.0000 90.0000" armature="0.01" damping="0" stiffness="0" frictionloss="1000"/>
              <geom type="mesh" mesh="R_Toe" contype="1" conaffinity="1" size="1 1 1" density="1000"/>
            </body>
          </body>
        </body>
      </body>
      <body name="Torso" pos="-0.0048 -0.1345 -0.0467" quat="1.0000 0.0000 0.0000 0.0000">
        <joint name="Torso_z" type="hinge" pos="-0.0048 -0.1345 -0.0467" axis="0 0 1" range="-35.0000 35.0000" armature="1000" damping="1000" stiffness="1000" frictionloss="1000"/>
        <joint name="Torso_y" type="hinge" pos="-0.0048 -0.1345 -0.0467" axis="0 1 0" range="-35.0000 35.0000" armature="1000" damping="1000" stiffness="1000" frictionloss="1000"/>
        <joint name="Torso_x" type="hinge" pos="-0.0048 -0.1345 -0.0467" axis="1 0 0" range="-35.0000 35.0000" armature="1000" damping="1000" stiffness="1000" frictionloss="1000"/>
        <geom type="mesh" mesh="Torso" contype="1" conaffinity="1" size="1 1 1" density="1000"/>
        <body name="Spine" pos="-0.0073 0.0014 -0.0105" quat="1.0000 0.0000 0.0000 0.0000">
          <joint name="Spine_z" type="hinge" pos="-0.0073 0.0014 -0.0105" axis="0 0 1" range="-35.0000 35.0000" armature="1000" damping="1000" stiffness="1000" frictionloss="1000"/>
          <joint name="Spine_y" type="hinge" pos="-0.0073 0.0014 -0.0105" axis="0 1 0" range="-35.0000 35.0000" armature="1000" damping="1000" stiffness="1000" frictionloss="1000"/>
          <joint name="Spine_x" type="hinge" pos="-0.0073 0.0014 -0.0105" axis="1 0 0" range="-35.0000 35.0000" armature="1000" damping="1000" stiffness="1000" frictionloss="1000"/>
          <geom type="mesh" mesh="Spine" contype="1" conaffinity="1" size="1 1 1" density="1000"/>
          <body name="Chest" pos="-0.012 0.057 -0.004" quat="1.0000 0.0000 0.0000 0.0000">
            <joint name="Chest_z" type="hinge" pos="-0.012 0.057 -0.004" axis="0 0 1" range="-35.0000 35.0000" armature="1000" damping="1000" stiffness="1000" frictionloss="1000"/>
            <joint name="Chest_y" type="hinge" pos="-0.012 0.057 -0.004" axis="0 1 0" range="-35.0000 35.0000" armature="1000" damping="1000" stiffness="1000" frictionloss="1000"/>
            <joint name="Chest_x" type="hinge" pos="-0.012 0.057 -0.004" axis="1 0 0" range="-35.0000 35.0000" armature="1000" damping="1000" stiffness="1000" frictionloss="1000"/>
            <geom type="mesh" mesh="Chest" contype="1" conaffinity="1" size="1 1 1" density="1000"/>
            <body name="Neck" pos="-0.0532 0.2676 -0.0024" quat="1.0000 0.0000 0.0000 0.0000">
              <joint name="Neck_z" type="hinge" pos="-0.0532 0.2676 -0.0024" axis="0 0 1" range="-35.0000 35.0000" armature="1000" damping="1000" stiffness="1000" frictionloss="1000"/>
              <joint name="Neck_y" type="hinge" pos="-0.0532 0.2676 -0.0024" axis="0 1 0" range="-35.0000 35.0000" armature="1000" damping="1000" stiffness="1000" frictionloss="1000"/>
              <joint name="Neck_x" type="hinge" pos="-0.0532 0.2676 -0.0024" axis="1 0 0" range="-35.0000 35.0000" armature="1000" damping="1000" stiffness="1000" frictionloss="1000"/>
              <geom type="mesh" mesh="Neck" contype="1" conaffinity="1" size="1 1 1" density="1000"/>
              <body name="Head" pos="-0.0652 0.3658 0.0253" quat="1.0000 0.0000 0.0000 0.0000">
                <joint name="Head_z" type="hinge" pos="-0.0652 0.3658 0.0253" axis="0 0 1" range="-35.0000 35.0000" armature="1000" damping="1000" stiffness="1000" frictionloss="1000"/>
                <joint name="Head_y" type="hinge" pos="-0.0652 0.3658 0.0253" axis="0 1 0" range="-35.0000 35.0000" armature="1000" damping="1000" stiffness="1000" frictionloss="1000"/>
                <joint name="Head_x" type="hinge" pos="-0.0652 0.3658 0.0253" axis="1 0 0" range="-35.0000 35.0000" armature="1000" damping="1000" stiffness="1000" frictionloss="1000"/>
                <geom type="mesh" mesh="Head" contype="1" conaffinity="1" size="1 1 1" density="1000"/>
              </body>
            </body>
            <body name="L_Thorax" pos="0.0409 0.1804 -0.0254" quat="1.0000 0.0000 0.0000 0.0000">
              <joint name="L_Thorax_z" type="hinge" pos="0.0409 0.1804 -0.0254" axis="0 0 1" range="-35.0000 35.0000" armature="0.01" damping="0" stiffness="0" frictionloss="1000"/>
              <joint name="L_Thorax_y" type="hinge" pos="0.0409 0.1804 -0.0254" axis="0 1 0" range="-35.0000 35.0000" armature="0.01" damping="0" stiffness="0" frictionloss="1000"/>
              <joint name="L_Thorax_x" type="hinge" pos="0.0409 0.1804 -0.0254" axis="1 0 0" range="-35.0000 35.0000" armature="0.01" damping="0" stiffness="0" frictionloss="1000"/>
              <geom type="mesh" mesh="L_Thorax" contype="1" conaffinity="1" size="1 1 1" density="1000"/>
              <body name="L_Shoulder" pos="0.1665 0.2212 -0.0336" quat="1.0000 0.0000 0.0000 0.0000">
                <joint name="L_Shoulder_z" type="hinge" pos="0.1665 0.2212 -0.0336" axis="0 0 1" range="-35.0000 35.0000" armature="0.01" damping="0" stiffness="0" frictionloss="1000"/>
                <joint name="L_Shoulder_y" type="hinge" pos="0.1665 0.2212 -0.0336" axis="0 1 0" range="-10.0000 30.0000" armature="0.01" damping="0" stiffness="0" frictionloss="1000"/>
                <joint name="L_Shoulder_x" type="hinge" pos="0.1665 0.2212 -0.0336" axis="1 0 0" range="-35.0000 35.0000" armature="0.01" damping="0" stiffness="0" frictionloss="1000"/>
                <geom type="mesh" mesh="L_Shoulder" contype="1" conaffinity="1" size="1 1 1" density="1000"/>
                <body name="L_Elbow" pos="0.2639 -0.0144 -0.0655" quat="1.0000 0.0000 0.0000 0.0000">
                  <joint name="L_Elbow_z" type="hinge" pos="0.2639 -0.0144 -0.0655" axis="0 0 1" range="-35.0000 35.0000" armature="0.01" damping="0" stiffness="0" frictionloss="1000"/>
                  <joint name="L_Elbow_y" type="hinge" pos="0.2639 -0.0144 -0.0655" axis="0 1 0" range="-35.0000 35.0000" armature="0.01" damping="0" stiffness="0" frictionloss="1000"/>
                  <joint name="L_Elbow_x" type="hinge" pos="0.2639 -0.0144 -0.0655" axis="1 0 0" range="-35.0000 35.0000" armature="0.01" damping="0" stiffness="0" frictionloss="1000"/>
                  <geom type="mesh" mesh="L_Elbow" contype="1" conaffinity="1" size="1 1 1" density="1000"/>
                  <body name="L_Wrist" pos="0.1069 -0.1167 0.1234" quat="1.0000 0.0000 0.0000 0.0000">
                    <joint name="L_Wrist_z" type="hinge" pos="0.1069 -0.1167 0.1234" axis="0 0 1" range="-35.0000 35.0000" armature="0.01" damping="0" stiffness="0" frictionloss="1000"/>
                    <joint name="L_Wrist_y" type="hinge" pos="0.1069 -0.1167 0.1234" axis="0 1 0" range="-35.0000 35.0000" armature="0.01" damping="0" stiffness="0" frictionloss="1000"/>
                    <joint name="L_Wrist_x" type="hinge" pos="0.1069 -0.1167 0.1234" axis="1 0 0" range="-35.0000 35.0000" armature="0.01" damping="0" stiffness="0" frictionloss="1000"/>
                    <geom type="mesh" mesh="L_Wrist" contype="1" conaffinity="1" size="1 1 1" density="1000"/>
                    <body name="L_Hand" pos="0.0366 -0.1599 0.1562" quat="1.0000 0.0000 0.0000 0.0000">
                      <joint name="L_Hand_z" type="hinge" pos="0.0366 -0.1599 0.1562" axis="0 0 1" range="-35.0000 35.0000" armature="0.01" damping="0" stiffness="0" frictionloss="1000"/>
                      <joint name="L_Hand_y" type="hinge" pos="0.0366 -0.1599 0.1562" axis="0 1 0" range="-35.0000 35.0000" armature="0.01" damping="0" stiffness="0" frictionloss="1000"/>
                      <joint name="L_Hand_x" type="hinge" pos="0.0366 -0.1599 0.1562" axis="1 0 0" range="-35.0000 35.0000" armature="0.01" damping="0" stiffness="0" frictionloss="1000"/>
                      <geom type="mesh" mesh="L_Hand" contype="1" conaffinity="1" size="1 1 1" density="1000"/>
                    </body>
                  </body>
                </body>
              </body>
            </body>
            <body name="R_Thorax" pos="-0.1079 0.1601 0.0118" quat="1.0000 0.0000 0.0000 0.0000">
              <joint name="R_Thorax_z" type="hinge" pos="-0.1079 0.1601 0.0118" axis="0 0 1" range="-35.0000 35.0000" armature="0.01" damping="0" stiffness="0" frictionloss="1000"/>
              <joint name="R_Thorax_y" type="hinge" pos="-0.1079 0.1601 0.0118" axis="0 1 0" range="-35.0000 35.0000" armature="0.01" damping="0" stiffness="0" frictionloss="1000"/>
              <joint name="R_Thorax_x" type="hinge" pos="-0.1079 0.1601 0.0118" axis="1 0 0" range="-35.0000 35.0000" armature="0.01" damping="0" stiffness="0" frictionloss="1000"/>
              <geom type="mesh" mesh="R_Thorax" contype="1" conaffinity="1" size="1 1 1" density="1000"/>
              <body name="R_Shoulder" pos="-0.2177 0.1996 0.0502" quat="1.0000 0.0000 0.0000 0.0000">
                <joint name="R_Shoulder_z" type="hinge" pos="-0.2177 0.1996 0.0502" axis="0 0 1" range="-35.0000 35.0000" armature="0.01" damping="0" stiffness="0" frictionloss="1000"/>
                <joint name="R_Shoulder_y" type="hinge" pos="-0.2177 0.1996 0.0502" axis="0 1 0" range="-35.0000 35.0000" armature="0.01" damping="0" stiffness="0" frictionloss="1000"/>
                <joint name="R_Shoulder_x" type="hinge" pos="-0.2177 0.1996 0.0502" axis="1 0 0" range="-35.0000 35.0000" armature="0.01" damping="0" stiffness="0" frictionloss="1000"/>
                <geom type="mesh" mesh="R_Shoulder" contype="1" conaffinity="1" size="1 1 1" density="1000"/>
                <body name="R_Elbow" pos="-0.2997 0.069 0.2624" quat="1.0000 0.0000 0.0000 0.0000">
                  <joint name="R_Elbow_z" type="hinge" pos="-0.2997 0.069 0.2624" axis="0 0 1" range="-35.0000 35.0000" armature="0.01" damping="0" stiffness="0" frictionloss="1000"/>
                  <joint name="R_Elbow_y" type="hinge" pos="-0.2997 0.069 0.2624" axis="0 1 0" range="-35.0000 35.0000" armature="0.01" damping="0" stiffness="0" frictionloss="1000"/>
                  <joint name="R_Elbow_x" type="hinge" pos="-0.2997 0.069 0.2624" axis="1 0 0" range="-35.0000 35.0000" armature="0.01" damping="0" stiffness="0" frictionloss="1000"/>
                  <geom type="mesh" mesh="R_Elbow" contype="1" conaffinity="1" size="1 1 1" density="1000"/>
                  <body name="R_Wrist" pos="-0.2465 0.3269 0.2064" quat="1.0000 0.0000 0.0000 0.0000">
                    <joint name="R_Wrist_z" type="hinge" pos="-0.2465 0.3269 0.2064" axis="0 0 1" range="-35.0000 35.0000" armature="0.01" damping="0" stiffness="0" frictionloss="1000"/>
                    <joint name="R_Wrist_y" type="hinge" pos="-0.2465 0.3269 0.2064" axis="0 1 0" range="-35.0000 35.0000" armature="0.01" damping="0" stiffness="0" frictionloss="1000"/>
                    <joint name="R_Wrist_x" type="hinge" pos="-0.2465 0.3269 0.2064" axis="1 0 0" range="-35.0000 35.0000" armature="0.01" damping="0" stiffness="0" frictionloss="1000"/>
                    <geom type="mesh" mesh="R_Wrist" contype="1" conaffinity="1" size="1 1 1" density="1000"/>
                    <body name="R_Hand" pos="-0.2173 0.4083 0.1822" quat="1.0000 0.0000 0.0000 0.0000">
                      <joint name="R_Hand_z" type="hinge" pos="-0.2173 0.4083 0.1822" axis="0 0 1" range="-35.0000 35.0000" armature="0.01" damping="0" stiffness="0" frictionloss="1000"/>
                      <joint name="R_Hand_y" type="hinge" pos="-0.2173 0.4083 0.1822" axis="0 1 0" range="-35.0000 35.0000" armature="0.01" damping="0" stiffness="0" frictionloss="1000"/>
                      <joint name="R_Hand_x" type="hinge" pos="-0.2173 0.4083 0.1822" axis="1 0 0" range="-35.0000 35.0000" armature="0.01" damping="0" stiffness="0" frictionloss="1000"/>
                      <geom type="mesh" mesh="R_Hand" contype="1" conaffinity="1" size="1 1 1" density="1000"/>
                    </body>
                  </body>
                </body>
              </body>
            </body>
          </body>
        </body>
      </body>
    </body>
  </worldbody>
  <actuator>
    <motor name="L_Hip_z" joint="L_Hip_z" gear="1"/>
    <motor name="L_Hip_y" joint="L_Hip_y" gear="1"/>
    <motor name="L_Hip_x" joint="L_Hip_x" gear="1"/>
    <motor name="L_Knee_z" joint="L_Knee_z" gear="1"/>
    <motor name="L_Knee_y" joint="L_Knee_y" gear="1"/>
    <motor name="L_Knee_x" joint="L_Knee_x" gear="1"/>
    <motor name="L_Ankle_z" joint="L_Ankle_z" gear="1"/>
    <motor name="L_Ankle_y" joint="L_Ankle_y" gear="1"/>
    <motor name="L_Ankle_x" joint="L_Ankle_x" gear="1"/>
    <motor name="L_Toe_z" joint="L_Toe_z" gear="1"/>
    <motor name="L_Toe_y" joint="L_Toe_y" gear="1"/>
    <motor name="L_Toe_x" joint="L_Toe_x" gear="1"/>
    <motor name="R_Hip_z" joint="R_Hip_z" gear="1"/>
    <motor name="R_Hip_y" joint="R_Hip_y" gear="1"/>
    <motor name="R_Hip_x" joint="R_Hip_x" gear="1"/>
    <motor name="R_Knee_z" joint="R_Knee_z" gear="1"/>
    <motor name="R_Knee_y" joint="R_Knee_y" gear="1"/>
    <motor name="R_Knee_x" joint="R_Knee_x" gear="1"/>
    <motor name="R_Ankle_z" joint="R_Ankle_z" gear="1"/>
    <motor name="R_Ankle_y" joint="R_Ankle_y" gear="1"/>
    <motor name="R_Ankle_x" joint="R_Ankle_x" gear="1"/>
    <motor name="R_Toe_z" joint="R_Toe_z" gear="1"/>
    <motor name="R_Toe_y" joint="R_Toe_y" gear="1"/>
    <motor name="R_Toe_x" joint="R_Toe_x" gear="1"/>
    <motor name="Torso_z" joint="Torso_z" gear="1"/>
    <motor name="Torso_y" joint="Torso_y" gear="1"/>
    <motor name="Torso_x" joint="Torso_x" gear="1"/>
    <motor name="Spine_z" joint="Spine_z" gear="1"/>
    <motor name="Spine_y" joint="Spine_y" gear="1"/>
    <motor name="Spine_x" joint="Spine_x" gear="1"/>
    <motor name="Chest_z" joint="Chest_z" gear="1"/>
    <motor name="Chest_y" joint="Chest_y" gear="1"/>
    <motor name="Chest_x" joint="Chest_x" gear="1"/>
    <motor name="Neck_z" joint="Neck_z" gear="1"/>
    <motor name="Neck_y" joint="Neck_y" gear="1"/>
    <motor name="Neck_x" joint="Neck_x" gear="1"/>
    <motor name="Head_z" joint="Head_z" gear="1"/>
    <motor name="Head_y" joint="Head_y" gear="1"/>
    <motor name="Head_x" joint="Head_x" gear="1"/>
    <motor name="L_Thorax_z" joint="L_Thorax_z" gear="1"/>
    <motor name="L_Thorax_y" joint="L_Thorax_y" gear="1"/>
    <motor name="L_Thorax_x" joint="L_Thorax_x" gear="1"/>
    <motor name="L_Shoulder_z" joint="L_Shoulder_z" gear="1"/>
    <motor name="L_Shoulder_y" joint="L_Shoulder_y" gear="1"/>
    <motor name="L_Shoulder_x" joint="L_Shoulder_x" gear="1"/>
    <motor name="L_Elbow_z" joint="L_Elbow_z" gear="1"/>
    <motor name="L_Elbow_y" joint="L_Elbow_y" gear="1"/>
    <motor name="L_Elbow_x" joint="L_Elbow_x" gear="1"/>
    <motor name="L_Wrist_z" joint="L_Wrist_z" gear="1"/>
    <motor name="L_Wrist_y" joint="L_Wrist_y" gear="1"/>
    <motor name="L_Wrist_x" joint="L_Wrist_x" gear="1"/>
    <motor name="L_Hand_z" joint="L_Hand_z" gear="1"/>
    <motor name="L_Hand_y" joint="L_Hand_y" gear="1"/>
    <motor name="L_Hand_x" joint="L_Hand_x" gear="1"/>
    <motor name="R_Thorax_z" joint="R_Thorax_z" gear="1"/>
    <motor name="R_Thorax_y" joint="R_Thorax_y" gear="1"/>
    <motor name="R_Thorax_x" joint="R_Thorax_x" gear="1"/>
    <motor name="R_Shoulder_z" joint="R_Shoulder_z" gear="1"/>
    <motor name="R_Shoulder_y" joint="R_Shoulder_y" gear="1"/>
    <motor name="R_Shoulder_x" joint="R_Shoulder_x" gear="1"/>
    <motor name="R_Elbow_z" joint="R_Elbow_z" gear="1"/>
    <motor name="R_Elbow_y" joint="R_Elbow_y" gear="1"/>
    <motor name="R_Elbow_x" joint="R_Elbow_x" gear="1"/>
    <motor name="R_Wrist_z" joint="R_Wrist_z" gear="1"/>
    <motor name="R_Wrist_y" joint="R_Wrist_y" gear="1"/>
    <motor name="R_Wrist_x" joint="R_Wrist_x" gear="1"/>
    <motor name="R_Hand_z" joint="R_Hand_z" gear="1"/>
    <motor name="R_Hand_y" joint="R_Hand_y" gear="1"/>
    <motor name="R_Hand_x" joint="R_Hand_x" gear="1"/>
  </actuator>
  <size njmax="2500" nconmax="500"/>
  <contact>
    <exclude name="add01" body1="L_Shoulder" body2="Chest"/>
    <exclude name="add02" body1="R_Shoulder" body2="Chest"/>
  </contact>
</mujoco>
