<mujoco model="humanoid">
  <compiler angle="degree" inertiafromgeom="true" coordinate="global"/>
  <visual>
    <headlight ambient=".4 .4 .4" diffuse=".8 .8 .8" specular="0.1 0.1 0.1"/>
    <map znear=".01"/>
    <quality shadowsize="2048"/>
  </visual>
  <default>
    <joint damping="0.0" armature="0.01" stiffness="0.0" limited="true"/>
    <geom conaffinity="1" condim="1" contype="7" margin="0.001" rgba="0.8 0.6 .4 1"/>
  </default>
  <statistic extent="3" center="0 0 1"/>
  <option timestep="0.00222222222"/>
  <asset>
    <texture type="skybox" builtin="gradient" rgb1=".4 .5 .6" rgb2="0 0 0" width="100" height="100"/>
    <texture builtin="flat" height="1278" mark="cross" markrgb="1 1 1" name="texgeom" random="0.01" rgb1="0.8 0.6 0.4" rgb2="0.8 0.6 0.4" type="cube" width="127"/>
    <texture builtin="checker" height="100" name="texplane" rgb1="0 0 0" rgb2="0.8 0.8 0.8" type="2d" width="100"/>
    <material name="MatPlane" reflectance="0.5" shininess="1" specular="1" texrepeat="60 60" texture="texplane"/>
    <material name="geom" texture="texgeom" texuniform="true"/>
    <mesh file="/home/louis/Documents/Projects/uhc-tri/assets/mujoco_models/geom/Pelvis.stl"/>
    <mesh file="/home/louis/Documents/Projects/uhc-tri/assets/mujoco_models/geom/L_Hip.stl"/>
    <mesh file="/home/louis/Documents/Projects/uhc-tri/assets/mujoco_models/geom/R_Hip.stl"/>
    <mesh file="/home/louis/Documents/Projects/uhc-tri/assets/mujoco_models/geom/Torso.stl"/>
    <mesh file="/home/louis/Documents/Projects/uhc-tri/assets/mujoco_models/geom/L_Knee.stl"/>
    <mesh file="/home/louis/Documents/Projects/uhc-tri/assets/mujoco_models/geom/R_Knee.stl"/>
    <mesh file="/home/louis/Documents/Projects/uhc-tri/assets/mujoco_models/geom/Spine.stl"/>
    <mesh file="/home/louis/Documents/Projects/uhc-tri/assets/mujoco_models/geom/L_Ankle.stl"/>
    <mesh file="/home/louis/Documents/Projects/uhc-tri/assets/mujoco_models/geom/R_Ankle.stl"/>
    <mesh file="/home/louis/Documents/Projects/uhc-tri/assets/mujoco_models/geom/Chest.stl"/>
    <mesh file="/home/louis/Documents/Projects/uhc-tri/assets/mujoco_models/geom/L_Toe.stl"/>
    <mesh file="/home/louis/Documents/Projects/uhc-tri/assets/mujoco_models/geom/R_Toe.stl"/>
    <mesh file="/home/louis/Documents/Projects/uhc-tri/assets/mujoco_models/geom/Neck.stl"/>
    <mesh file="/home/louis/Documents/Projects/uhc-tri/assets/mujoco_models/geom/L_Thorax.stl"/>
    <mesh file="/home/louis/Documents/Projects/uhc-tri/assets/mujoco_models/geom/R_Thorax.stl"/>
    <mesh file="/home/louis/Documents/Projects/uhc-tri/assets/mujoco_models/geom/Head.stl"/>
    <mesh file="/home/louis/Documents/Projects/uhc-tri/assets/mujoco_models/geom/L_Shoulder.stl"/>
    <mesh file="/home/louis/Documents/Projects/uhc-tri/assets/mujoco_models/geom/R_Shoulder.stl"/>
    <mesh file="/home/louis/Documents/Projects/uhc-tri/assets/mujoco_models/geom/L_Elbow.stl"/>
    <mesh file="/home/louis/Documents/Projects/uhc-tri/assets/mujoco_models/geom/R_Elbow.stl"/>
    <mesh file="/home/louis/Documents/Projects/uhc-tri/assets/mujoco_models/geom/L_Wrist.stl"/>
    <mesh file="/home/louis/Documents/Projects/uhc-tri/assets/mujoco_models/geom/R_Wrist.stl"/>
    <mesh file="/home/louis/Documents/Projects/uhc-tri/assets/mujoco_models/geom/L_Hand.stl"/>
    <mesh file="/home/louis/Documents/Projects/uhc-tri/assets/mujoco_models/geom/R_Hand.stl"/>
  </asset>
  <worldbody>
    <light cutoff="100" diffuse="1 1 1" dir="-0 0 -1.3" directional="true" exponent="1" pos="0 0 1.3" specular=".1 .1 .1"/>
    <geom conaffinity="1" condim="3" name="floor" pos="0 0 0" rgba="0.8 0.9 0.8 1" size="100 100 .2" type="plane" material="MatPlane"/>
    <body name="Pelvis" pos="-0.0022 -0.2408 0.0286" quat="1.0000 0.0000 0.0000 0.0000">
      <joint name="Pelvis" pos="-0.0022 -0.2408 0.0286" limited="false" type="free" armature="0.01" damping="0" stiffness="0" frictionloss="1000"/>
      <geom type="mesh" mesh="Pelvis" contype="1" conaffinity="1" size="1 1 1" density="1000"/>
      <body name="L_Hip" pos="0.0468 -0.3289 0.0474" quat="1.0000 0.0000 0.0000 0.0000">
        <joint name="L_Hip_z" type="hinge" pos="0.0468 -0.3289 0.0474" axis="0 0 1" range="-35.0000 35.0000" armature="0.01" damping="0" stiffness="0" frictionloss="1000"/>
        <joint name="L_Hip_y" type="hinge" pos="0.0468 -0.3289 0.0474" axis="0 1 0" range="-35.0000 35.0000" armature="0.01" damping="0" stiffness="0" frictionloss="1000"/>
        <joint name="L_Hip_x" type="hinge" pos="0.0468 -0.3289 0.0474" axis="1 0 0" range="-35.0000 35.0000" armature="0.01" damping="0" stiffness="0" frictionloss="1000"/>
        <geom type="mesh" mesh="L_Hip" contype="1" conaffinity="1" size="1 1 1" density="1000"/>
        <body name="L_Knee" pos="0.2047 -0.5908 0.2877" quat="1.0000 0.0000 0.0000 0.0000">
          <joint name="L_Knee_z" type="hinge" pos="0.2047 -0.5908 0.2877" axis="0 0 1" range="-11.2500 11.2500" armature="0.01" damping="0" stiffness="0" frictionloss="1000"/>
          <joint name="L_Knee_y" type="hinge" pos="0.2047 -0.5908 0.2877" axis="0 1 0" range="-11.2500 11.2500" armature="0.01" damping="0" stiffness="0" frictionloss="1000"/>
          <joint name="L_Knee_x" type="hinge" pos="0.2047 -0.5908 0.2877" axis="1 0 0" range="-11.2500 180.0000" armature="0.01" damping="0" stiffness="0" frictionloss="1000"/>
          <geom type="mesh" mesh="L_Knee" contype="1" conaffinity="1" size="1 1 1" density="1000"/>
          <body name="L_Ankle" pos="-0.0252 -0.948 0.2297" quat="1.0000 0.0000 0.0000 0.0000">
            <joint name="L_Ankle_z" type="hinge" pos="-0.0252 -0.948 0.2297" axis="0 0 1" range="-90.0000 90.0000" armature="0.01" damping="0" stiffness="0" frictionloss="1000"/>
            <joint name="L_Ankle_y" type="hinge" pos="-0.0252 -0.948 0.2297" axis="0 1 0" range="-90.0000 90.0000" armature="0.01" damping="0" stiffness="0" frictionloss="1000"/>
            <joint name="L_Ankle_x" type="hinge" pos="-0.0252 -0.948 0.2297" axis="1 0 0" range="-90.0000 90.0000" armature="0.01" damping="0" stiffness="0" frictionloss="1000"/>
            <geom type="mesh" mesh="L_Ankle" contype="1" conaffinity="1" size="1 1 1" density="1000"/>
            <body name="L_Toe" pos="0.003 -1.0864 0.2457" quat="1.0000 0.0000 0.0000 0.0000">
              <joint name="L_Toe_z" type="hinge" pos="0.003 -1.0864 0.2457" axis="0 0 1" range="-45.0000 45.0000" armature="0.01" damping="0" stiffness="0" frictionloss="1000"/>
              <joint name="L_Toe_y" type="hinge" pos="0.003 -1.0864 0.2457" axis="0 1 0" range="-45.0000 45.0000" armature="0.01" damping="0" stiffness="0" frictionloss="1000"/>
              <joint name="L_Toe_x" type="hinge" pos="0.003 -1.0864 0.2457" axis="1 0 0" range="-90.0000 90.0000" armature="0.01" damping="0" stiffness="0" frictionloss="1000"/>
              <geom type="mesh" mesh="L_Toe" contype="1" conaffinity="1" size="1 1 1" density="1000"/>
            </body>
          </body>
        </body>
      </body>
      <body name="R_Hip" pos="-0.072 -0.3213 0.0539" quat="1.0000 0.0000 0.0000 0.0000">
        <joint name="R_Hip_z" type="hinge" pos="-0.072 -0.3213 0.0539" axis="0 0 1" range="-35.0000 35.0000" armature="0.01" damping="0" stiffness="0" frictionloss="1000"/>
        <joint name="R_Hip_y" type="hinge" pos="-0.072 -0.3213 0.0539" axis="0 1 0" range="-35.0000 35.0000" armature="0.01" damping="0" stiffness="0" frictionloss="1000"/>
        <joint name="R_Hip_x" type="hinge" pos="-0.072 -0.3213 0.0539" axis="1 0 0" range="-35.0000 35.0000" armature="0.01" damping="0" stiffness="0" frictionloss="1000"/>
        <geom type="mesh" mesh="R_Hip" contype="1" conaffinity="1" size="1 1 1" density="1000"/>
        <body name="R_Knee" pos="0.1045 -0.4852 0.3558" quat="1.0000 0.0000 0.0000 0.0000">
          <joint name="R_Knee_z" type="hinge" pos="0.1045 -0.4852 0.3558" axis="0 0 1" range="-11.2500 11.2500" armature="0.01" damping="0" stiffness="0" frictionloss="1000"/>
          <joint name="R_Knee_y" type="hinge" pos="0.1045 -0.4852 0.3558" axis="0 1 0" range="-11.2500 11.2500" armature="0.01" damping="0" stiffness="0" frictionloss="1000"/>
          <joint name="R_Knee_x" type="hinge" pos="0.1045 -0.4852 0.3558" axis="1 0 0" range="-11.2500 180.0000" armature="0.01" damping="0" stiffness="0" frictionloss="1000"/>
          <geom type="mesh" mesh="R_Knee" contype="1" conaffinity="1" size="1 1 1" density="1000"/>
          <body name="R_Ankle" pos="0.0202 -0.8946 0.2987" quat="1.0000 0.0000 0.0000 0.0000">
            <joint name="R_Ankle_z" type="hinge" pos="0.0202 -0.8946 0.2987" axis="0 0 1" range="-90.0000 90.0000" armature="0.01" damping="0" stiffness="0" frictionloss="1000"/>
            <joint name="R_Ankle_y" type="hinge" pos="0.0202 -0.8946 0.2987" axis="0 1 0" range="-90.0000 90.0000" armature="0.01" damping="0" stiffness="0" frictionloss="1000"/>
            <joint name="R_Ankle_x" type="hinge" pos="0.0202 -0.8946 0.2987" axis="1 0 0" range="-90.0000 90.0000" armature="0.01" damping="0" stiffness="0" frictionloss="1000"/>
            <geom type="mesh" mesh="R_Ankle" contype="1" conaffinity="1" size="1 1 1" density="1000"/>
            <body name="R_Toe" pos="0.0227 -1.0228 0.3737" quat="1.0000 0.0000 0.0000 0.0000">
              <joint name="R_Toe_z" type="hinge" pos="0.0227 -1.0228 0.3737" axis="0 0 1" range="-45.0000 45.0000" armature="0.01" damping="0" stiffness="0" frictionloss="1000"/>
              <joint name="R_Toe_y" type="hinge" pos="0.0227 -1.0228 0.3737" axis="0 1 0" range="-45.0000 45.0000" armature="0.01" damping="0" stiffness="0" frictionloss="1000"/>
              <joint name="R_Toe_x" type="hinge" pos="0.0227 -1.0228 0.3737" axis="1 0 0" range="-90.0000 90.0000" armature="0.01" damping="0" stiffness="0" frictionloss="1000"/>
              <geom type="mesh" mesh="R_Toe" contype="1" conaffinity="1" size="1 1 1" density="1000"/>
            </body>
          </body>
        </body>
      </body>
      <body name="Torso" pos="0.0135 -0.1451 -0.0584" quat="1.0000 0.0000 0.0000 0.0000">
        <joint name="Torso_z" type="hinge" pos="0.0135 -0.1451 -0.0584" axis="0 0 1" range="-35.0000 35.0000" armature="0.01" damping="0" stiffness="0" frictionloss="1000"/>
        <joint name="Torso_y" type="hinge" pos="0.0135 -0.1451 -0.0584" axis="0 1 0" range="-35.0000 35.0000" armature="0.01" damping="0" stiffness="0" frictionloss="1000"/>
        <joint name="Torso_x" type="hinge" pos="0.0135 -0.1451 -0.0584" axis="1 0 0" range="-35.0000 35.0000" armature="0.01" damping="0" stiffness="0" frictionloss="1000"/>
        <geom type="mesh" mesh="Torso" contype="1" conaffinity="1" size="1 1 1" density="1000"/>
        <body name="Spine" pos="0.0353 -0.0091 -0.0303" quat="1.0000 0.0000 0.0000 0.0000">
          <joint name="Spine_z" type="hinge" pos="0.0353 -0.0091 -0.0303" axis="0 0 1" range="-35.0000 35.0000" armature="0.01" damping="0" stiffness="0" frictionloss="1000"/>
          <joint name="Spine_y" type="hinge" pos="0.0353 -0.0091 -0.0303" axis="0 1 0" range="-35.0000 35.0000" armature="0.01" damping="0" stiffness="0" frictionloss="1000"/>
          <joint name="Spine_x" type="hinge" pos="0.0353 -0.0091 -0.0303" axis="1 0 0" range="-35.0000 35.0000" armature="0.01" damping="0" stiffness="0" frictionloss="1000"/>
          <geom type="mesh" mesh="Spine" contype="1" conaffinity="1" size="1 1 1" density="1000"/>
          <body name="Chest" pos="0.042 0.0459 -0.0213" quat="1.0000 0.0000 0.0000 0.0000">
            <joint name="Chest_z" type="hinge" pos="0.042 0.0459 -0.0213" axis="0 0 1" range="-35.0000 35.0000" armature="0.01" damping="0" stiffness="0" frictionloss="1000"/>
            <joint name="Chest_y" type="hinge" pos="0.042 0.0459 -0.0213" axis="0 1 0" range="-35.0000 35.0000" armature="0.01" damping="0" stiffness="0" frictionloss="1000"/>
            <joint name="Chest_x" type="hinge" pos="0.042 0.0459 -0.0213" axis="1 0 0" range="-35.0000 35.0000" armature="0.01" damping="0" stiffness="0" frictionloss="1000"/>
            <geom type="mesh" mesh="Chest" contype="1" conaffinity="1" size="1 1 1" density="1000"/>
            <body name="Neck" pos="0.0891 0.2553 -0.0157" quat="1.0000 0.0000 0.0000 0.0000">
              <joint name="Neck_z" type="hinge" pos="0.0891 0.2553 -0.0157" axis="0 0 1" range="-35.0000 35.0000" armature="0.01" damping="0" stiffness="0" frictionloss="1000"/>
              <joint name="Neck_y" type="hinge" pos="0.0891 0.2553 -0.0157" axis="0 1 0" range="-35.0000 35.0000" armature="0.01" damping="0" stiffness="0" frictionloss="1000"/>
              <joint name="Neck_x" type="hinge" pos="0.0891 0.2553 -0.0157" axis="1 0 0" range="-35.0000 35.0000" armature="0.01" damping="0" stiffness="0" frictionloss="1000"/>
              <geom type="mesh" mesh="Neck" contype="1" conaffinity="1" size="1 1 1" density="1000"/>
              <body name="Head" pos="0.1347 0.339 0.0225" quat="1.0000 0.0000 0.0000 0.0000">
                <joint name="Head_z" type="hinge" pos="0.1347 0.339 0.0225" axis="0 0 1" range="-35.0000 35.0000" armature="0.01" damping="0" stiffness="0" frictionloss="1000"/>
                <joint name="Head_y" type="hinge" pos="0.1347 0.339 0.0225" axis="0 1 0" range="-35.0000 35.0000" armature="0.01" damping="0" stiffness="0" frictionloss="1000"/>
                <joint name="Head_x" type="hinge" pos="0.1347 0.339 0.0225" axis="1 0 0" range="-35.0000 35.0000" armature="0.01" damping="0" stiffness="0" frictionloss="1000"/>
                <geom type="mesh" mesh="Head" contype="1" conaffinity="1" size="1 1 1" density="1000"/>
              </body>
            </body>
            <body name="L_Thorax" pos="0.142 0.1366 -0.0049" quat="1.0000 0.0000 0.0000 0.0000">
              <joint name="L_Thorax_z" type="hinge" pos="0.142 0.1366 -0.0049" axis="0 0 1" range="-35.0000 35.0000" armature="0.01" damping="0" stiffness="0" frictionloss="1000"/>
              <joint name="L_Thorax_y" type="hinge" pos="0.142 0.1366 -0.0049" axis="0 1 0" range="-35.0000 35.0000" armature="0.01" damping="0" stiffness="0" frictionloss="1000"/>
              <joint name="L_Thorax_x" type="hinge" pos="0.142 0.1366 -0.0049" axis="1 0 0" range="-35.0000 35.0000" armature="0.01" damping="0" stiffness="0" frictionloss="1000"/>
              <geom type="mesh" mesh="L_Thorax" contype="1" conaffinity="1" size="1 1 1" density="1000"/>
              <body name="L_Shoulder" pos="0.2606 0.1559 0.0504" quat="1.0000 0.0000 0.0000 0.0000">
                <joint name="L_Shoulder_z" type="hinge" pos="0.2606 0.1559 0.0504" axis="0 0 1" range="-35.0000 35.0000" armature="0.01" damping="0" stiffness="0" frictionloss="1000"/>
                <joint name="L_Shoulder_y" type="hinge" pos="0.2606 0.1559 0.0504" axis="0 1 0" range="-10.0000 30.0000" armature="0.01" damping="0" stiffness="0" frictionloss="1000"/>
                <joint name="L_Shoulder_x" type="hinge" pos="0.2606 0.1559 0.0504" axis="1 0 0" range="-35.0000 35.0000" armature="0.01" damping="0" stiffness="0" frictionloss="1000"/>
                <geom type="mesh" mesh="L_Shoulder" contype="1" conaffinity="1" size="1 1 1" density="1000"/>
                <body name="L_Elbow" pos="0.2676 -0.0805 0.1505" quat="1.0000 0.0000 0.0000 0.0000">
                  <joint name="L_Elbow_z" type="hinge" pos="0.2676 -0.0805 0.1505" axis="0 0 1" range="-35.0000 35.0000" armature="0.01" damping="0" stiffness="0" frictionloss="1000"/>
                  <joint name="L_Elbow_y" type="hinge" pos="0.2676 -0.0805 0.1505" axis="0 1 0" range="-35.0000 35.0000" armature="0.01" damping="0" stiffness="0" frictionloss="1000"/>
                  <joint name="L_Elbow_x" type="hinge" pos="0.2676 -0.0805 0.1505" axis="1 0 0" range="-35.0000 35.0000" armature="0.01" damping="0" stiffness="0" frictionloss="1000"/>
                  <geom type="mesh" mesh="L_Elbow" contype="1" conaffinity="1" size="1 1 1" density="1000"/>
                  <body name="L_Wrist" pos="0.2228 -0.0765 0.4127" quat="1.0000 0.0000 0.0000 0.0000">
                    <joint name="L_Wrist_z" type="hinge" pos="0.2228 -0.0765 0.4127" axis="0 0 1" range="-35.0000 35.0000" armature="0.01" damping="0" stiffness="0" frictionloss="1000"/>
                    <joint name="L_Wrist_y" type="hinge" pos="0.2228 -0.0765 0.4127" axis="0 1 0" range="-35.0000 35.0000" armature="0.01" damping="0" stiffness="0" frictionloss="1000"/>
                    <joint name="L_Wrist_x" type="hinge" pos="0.2228 -0.0765 0.4127" axis="1 0 0" range="-35.0000 35.0000" armature="0.01" damping="0" stiffness="0" frictionloss="1000"/>
                    <geom type="mesh" mesh="L_Wrist" contype="1" conaffinity="1" size="1 1 1" density="1000"/>
                    <body name="L_Hand" pos="0.1938 -0.0873 0.4959" quat="1.0000 0.0000 0.0000 0.0000">
                      <joint name="L_Hand_z" type="hinge" pos="0.1938 -0.0873 0.4959" axis="0 0 1" range="-35.0000 35.0000" armature="0.01" damping="0" stiffness="0" frictionloss="1000"/>
                      <joint name="L_Hand_y" type="hinge" pos="0.1938 -0.0873 0.4959" axis="0 1 0" range="-35.0000 35.0000" armature="0.01" damping="0" stiffness="0" frictionloss="1000"/>
                      <joint name="L_Hand_x" type="hinge" pos="0.1938 -0.0873 0.4959" axis="1 0 0" range="-35.0000 35.0000" armature="0.01" damping="0" stiffness="0" frictionloss="1000"/>
                      <geom type="mesh" mesh="L_Hand" contype="1" conaffinity="1" size="1 1 1" density="1000"/>
                    </body>
                  </body>
                </body>
              </body>
            </body>
            <body name="R_Thorax" pos="-0.0031 0.1793 -0.0377" quat="1.0000 0.0000 0.0000 0.0000">
              <joint name="R_Thorax_z" type="hinge" pos="-0.0031 0.1793 -0.0377" axis="0 0 1" range="-35.0000 35.0000" armature="0.01" damping="0" stiffness="0" frictionloss="1000"/>
              <joint name="R_Thorax_y" type="hinge" pos="-0.0031 0.1793 -0.0377" axis="0 1 0" range="-35.0000 35.0000" armature="0.01" damping="0" stiffness="0" frictionloss="1000"/>
              <joint name="R_Thorax_x" type="hinge" pos="-0.0031 0.1793 -0.0377" axis="1 0 0" range="-35.0000 35.0000" armature="0.01" damping="0" stiffness="0" frictionloss="1000"/>
              <geom type="mesh" mesh="R_Thorax" contype="1" conaffinity="1" size="1 1 1" density="1000"/>
              <body name="R_Shoulder" pos="-0.1159 0.2211 -0.0128" quat="1.0000 0.0000 0.0000 0.0000">
                <joint name="R_Shoulder_z" type="hinge" pos="-0.1159 0.2211 -0.0128" axis="0 0 1" range="-35.0000 35.0000" armature="0.01" damping="0" stiffness="0" frictionloss="1000"/>
                <joint name="R_Shoulder_y" type="hinge" pos="-0.1159 0.2211 -0.0128" axis="0 1 0" range="-35.0000 35.0000" armature="0.01" damping="0" stiffness="0" frictionloss="1000"/>
                <joint name="R_Shoulder_x" type="hinge" pos="-0.1159 0.2211 -0.0128" axis="1 0 0" range="-35.0000 35.0000" armature="0.01" damping="0" stiffness="0" frictionloss="1000"/>
                <geom type="mesh" mesh="R_Shoulder" contype="1" conaffinity="1" size="1 1 1" density="1000"/>
                <body name="R_Elbow" pos="-0.1996 -0.0275 -0.0203" quat="1.0000 0.0000 0.0000 0.0000">
                  <joint name="R_Elbow_z" type="hinge" pos="-0.1996 -0.0275 -0.0203" axis="0 0 1" range="-35.0000 35.0000" armature="0.01" damping="0" stiffness="0" frictionloss="1000"/>
                  <joint name="R_Elbow_y" type="hinge" pos="-0.1996 -0.0275 -0.0203" axis="0 1 0" range="-35.0000 35.0000" armature="0.01" damping="0" stiffness="0" frictionloss="1000"/>
                  <joint name="R_Elbow_x" type="hinge" pos="-0.1996 -0.0275 -0.0203" axis="1 0 0" range="-35.0000 35.0000" armature="0.01" damping="0" stiffness="0" frictionloss="1000"/>
                  <geom type="mesh" mesh="R_Elbow" contype="1" conaffinity="1" size="1 1 1" density="1000"/>
                  <body name="R_Wrist" pos="-0.0597 -0.2146 0.1136" quat="1.0000 0.0000 0.0000 0.0000">
                    <joint name="R_Wrist_z" type="hinge" pos="-0.0597 -0.2146 0.1136" axis="0 0 1" range="-35.0000 35.0000" armature="0.01" damping="0" stiffness="0" frictionloss="1000"/>
                    <joint name="R_Wrist_y" type="hinge" pos="-0.0597 -0.2146 0.1136" axis="0 1 0" range="-35.0000 35.0000" armature="0.01" damping="0" stiffness="0" frictionloss="1000"/>
                    <joint name="R_Wrist_x" type="hinge" pos="-0.0597 -0.2146 0.1136" axis="1 0 0" range="-35.0000 35.0000" armature="0.01" damping="0" stiffness="0" frictionloss="1000"/>
                    <geom type="mesh" mesh="R_Wrist" contype="1" conaffinity="1" size="1 1 1" density="1000"/>
                    <body name="R_Hand" pos="-0.0033 -0.2789 0.1407" quat="1.0000 0.0000 0.0000 0.0000">
                      <joint name="R_Hand_z" type="hinge" pos="-0.0033 -0.2789 0.1407" axis="0 0 1" range="-35.0000 35.0000" armature="0.01" damping="0" stiffness="0" frictionloss="1000"/>
                      <joint name="R_Hand_y" type="hinge" pos="-0.0033 -0.2789 0.1407" axis="0 1 0" range="-35.0000 35.0000" armature="0.01" damping="0" stiffness="0" frictionloss="1000"/>
                      <joint name="R_Hand_x" type="hinge" pos="-0.0033 -0.2789 0.1407" axis="1 0 0" range="-35.0000 35.0000" armature="0.01" damping="0" stiffness="0" frictionloss="1000"/>
                      <geom type="mesh" mesh="R_Hand" contype="1" conaffinity="1" size="1 1 1" density="1000"/>
                    </body>
                  </body>
                </body>
              </body>
            </body>
          </body>
        </body>
      </body>
    </body>
  </worldbody>
  <actuator>
    <motor name="L_Hip_z" joint="L_Hip_z" gear="1"/>
    <motor name="L_Hip_y" joint="L_Hip_y" gear="1"/>
    <motor name="L_Hip_x" joint="L_Hip_x" gear="1"/>
    <motor name="L_Knee_z" joint="L_Knee_z" gear="1"/>
    <motor name="L_Knee_y" joint="L_Knee_y" gear="1"/>
    <motor name="L_Knee_x" joint="L_Knee_x" gear="1"/>
    <motor name="L_Ankle_z" joint="L_Ankle_z" gear="1"/>
    <motor name="L_Ankle_y" joint="L_Ankle_y" gear="1"/>
    <motor name="L_Ankle_x" joint="L_Ankle_x" gear="1"/>
    <motor name="L_Toe_z" joint="L_Toe_z" gear="1"/>
    <motor name="L_Toe_y" joint="L_Toe_y" gear="1"/>
    <motor name="L_Toe_x" joint="L_Toe_x" gear="1"/>
    <motor name="R_Hip_z" joint="R_Hip_z" gear="1"/>
    <motor name="R_Hip_y" joint="R_Hip_y" gear="1"/>
    <motor name="R_Hip_x" joint="R_Hip_x" gear="1"/>
    <motor name="R_Knee_z" joint="R_Knee_z" gear="1"/>
    <motor name="R_Knee_y" joint="R_Knee_y" gear="1"/>
    <motor name="R_Knee_x" joint="R_Knee_x" gear="1"/>
    <motor name="R_Ankle_z" joint="R_Ankle_z" gear="1"/>
    <motor name="R_Ankle_y" joint="R_Ankle_y" gear="1"/>
    <motor name="R_Ankle_x" joint="R_Ankle_x" gear="1"/>
    <motor name="R_Toe_z" joint="R_Toe_z" gear="1"/>
    <motor name="R_Toe_y" joint="R_Toe_y" gear="1"/>
    <motor name="R_Toe_x" joint="R_Toe_x" gear="1"/>
    <motor name="Torso_z" joint="Torso_z" gear="1"/>
    <motor name="Torso_y" joint="Torso_y" gear="1"/>
    <motor name="Torso_x" joint="Torso_x" gear="1"/>
    <motor name="Spine_z" joint="Spine_z" gear="1"/>
    <motor name="Spine_y" joint="Spine_y" gear="1"/>
    <motor name="Spine_x" joint="Spine_x" gear="1"/>
    <motor name="Chest_z" joint="Chest_z" gear="1"/>
    <motor name="Chest_y" joint="Chest_y" gear="1"/>
    <motor name="Chest_x" joint="Chest_x" gear="1"/>
    <motor name="Neck_z" joint="Neck_z" gear="1"/>
    <motor name="Neck_y" joint="Neck_y" gear="1"/>
    <motor name="Neck_x" joint="Neck_x" gear="1"/>
    <motor name="Head_z" joint="Head_z" gear="1"/>
    <motor name="Head_y" joint="Head_y" gear="1"/>
    <motor name="Head_x" joint="Head_x" gear="1"/>
    <motor name="L_Thorax_z" joint="L_Thorax_z" gear="1"/>
    <motor name="L_Thorax_y" joint="L_Thorax_y" gear="1"/>
    <motor name="L_Thorax_x" joint="L_Thorax_x" gear="1"/>
    <motor name="L_Shoulder_z" joint="L_Shoulder_z" gear="1"/>
    <motor name="L_Shoulder_y" joint="L_Shoulder_y" gear="1"/>
    <motor name="L_Shoulder_x" joint="L_Shoulder_x" gear="1"/>
    <motor name="L_Elbow_z" joint="L_Elbow_z" gear="1"/>
    <motor name="L_Elbow_y" joint="L_Elbow_y" gear="1"/>
    <motor name="L_Elbow_x" joint="L_Elbow_x" gear="1"/>
    <motor name="L_Wrist_z" joint="L_Wrist_z" gear="1"/>
    <motor name="L_Wrist_y" joint="L_Wrist_y" gear="1"/>
    <motor name="L_Wrist_x" joint="L_Wrist_x" gear="1"/>
    <motor name="L_Hand_z" joint="L_Hand_z" gear="1"/>
    <motor name="L_Hand_y" joint="L_Hand_y" gear="1"/>
    <motor name="L_Hand_x" joint="L_Hand_x" gear="1"/>
    <motor name="R_Thorax_z" joint="R_Thorax_z" gear="1"/>
    <motor name="R_Thorax_y" joint="R_Thorax_y" gear="1"/>
    <motor name="R_Thorax_x" joint="R_Thorax_x" gear="1"/>
    <motor name="R_Shoulder_z" joint="R_Shoulder_z" gear="1"/>
    <motor name="R_Shoulder_y" joint="R_Shoulder_y" gear="1"/>
    <motor name="R_Shoulder_x" joint="R_Shoulder_x" gear="1"/>
    <motor name="R_Elbow_z" joint="R_Elbow_z" gear="1"/>
    <motor name="R_Elbow_y" joint="R_Elbow_y" gear="1"/>
    <motor name="R_Elbow_x" joint="R_Elbow_x" gear="1"/>
    <motor name="R_Wrist_z" joint="R_Wrist_z" gear="1"/>
    <motor name="R_Wrist_y" joint="R_Wrist_y" gear="1"/>
    <motor name="R_Wrist_x" joint="R_Wrist_x" gear="1"/>
    <motor name="R_Hand_z" joint="R_Hand_z" gear="1"/>
    <motor name="R_Hand_y" joint="R_Hand_y" gear="1"/>
    <motor name="R_Hand_x" joint="R_Hand_x" gear="1"/>
  </actuator>
  <size njmax="2500" nconmax="500"/>
  <contact>
    <exclude name="add01" body1="L_Shoulder" body2="Chest"/>
    <exclude name="add02" body1="R_Shoulder" body2="Chest"/>
  </contact>
</mujoco>
